{
   "assignee" : null,
   "assignees" : [],
   "body" : "I had this problem once while I was running the `walletbackup.py` test on 0.13:\r\n```\r\nwalletbackup.py:\r\nInitializing test directory /tmp/testo3khmc00/37\r\nINFO: Generating initial blockchain\r\nAssertion failed: 76.69962300 != 50\r\nStopping nodes\r\nNot cleaning up dir /tmp/testo3khmc00/37\r\nFailed\r\n\r\nstderr:\r\n Error: Unable to start HTTP server. See debug log for details.\r\n\r\n\r\n************************\r\nEXCEPTION: N5boost16exception_detail10clone_implINS0_19error_info_injectorINS_10lock_errorEEEEE       \r\nboost: mutex lock failed in pthread_mutex_lock: Invalid argument       \r\nbitcoin in scheduler       \r\n\r\n  File \"/data/src/bitcoin-0.13/qa/rpc-tests/test_framework/test_framework.py\", line 148, in main\r\n    self.run_test()\r\n  File \"/home/user/src/bitcoin-0.13/qa/rpc-tests/walletbackup.py\", line 114, in run_test\r\n    assert_equal(self.nodes[0].getbalance(), 50)\r\n  File \"/data/src/bitcoin-0.13/qa/rpc-tests/test_framework/util.py\", line 496, in assert_equal\r\n    raise AssertionError(\"%s != %s\"%(str(thing1),str(thing2)))\r\n```\r\nI'm unfortunately unable to reproduce it again, looks like a race condition.\r\n\r\nData directory available here: https://dev.visucore.com/bitcoin/tmp/8425_failed_testdata.tar.gz\r\n",
   "closed_at" : null,
   "closed_by" : null,
   "comments" : 2,
   "comments_url" : "https://api.github.com/repos/bitcoin/bitcoin/issues/8425/comments",
   "created_at" : "2016-07-29T08:23:16Z",
   "events_url" : "https://api.github.com/repos/bitcoin/bitcoin/issues/8425/events",
   "html_url" : "https://github.com/bitcoin/bitcoin/issues/8425",
   "id" : 168274559,
   "labels" : [
      {
         "color" : "d4c5f9",
         "name" : "Tests",
         "url" : "https://api.github.com/repos/bitcoin/bitcoin/labels/Tests"
      }
   ],
   "labels_url" : "https://api.github.com/repos/bitcoin/bitcoin/issues/8425/labels{/name}",
   "locked" : false,
   "milestone" : null,
   "number" : 8425,
   "repository_url" : "https://api.github.com/repos/bitcoin/bitcoin",
   "state" : "open",
   "title" : "Rare walletbackup.py failure: cannot reproduce",
   "updated_at" : "2016-07-29T08:57:13Z",
   "url" : "https://api.github.com/repos/bitcoin/bitcoin/issues/8425",
   "user" : {
      "avatar_url" : "https://avatars.githubusercontent.com/u/126646?v=3",
      "events_url" : "https://api.github.com/users/laanwj/events{/privacy}",
      "followers_url" : "https://api.github.com/users/laanwj/followers",
      "following_url" : "https://api.github.com/users/laanwj/following{/other_user}",
      "gists_url" : "https://api.github.com/users/laanwj/gists{/gist_id}",
      "gravatar_id" : "",
      "html_url" : "https://github.com/laanwj",
      "id" : 126646,
      "login" : "laanwj",
      "organizations_url" : "https://api.github.com/users/laanwj/orgs",
      "received_events_url" : "https://api.github.com/users/laanwj/received_events",
      "repos_url" : "https://api.github.com/users/laanwj/repos",
      "site_admin" : false,
      "starred_url" : "https://api.github.com/users/laanwj/starred{/owner}{/repo}",
      "subscriptions_url" : "https://api.github.com/users/laanwj/subscriptions",
      "type" : "User",
      "url" : "https://api.github.com/users/laanwj"
   }
}
